<?xml version="1.0" ?>
<!-- =================================================================================== -->
<!-- |    This document was autogenerated by xacro from src/diff_bot/urdf/gazebo_sim.xml | -->
<!-- |    EDITING THIS FILE BY HAND IS NOT RECOMMENDED                                 | -->
<!-- =================================================================================== -->
<robot name="diff_bot">
  <material name="white">
    <color rgba="1 1 1 1"/>
  </material>
  <material name="orange">
    <color rgba="1 0.3 0.1 1"/>
  </material>
  <material name="blue">
    <color rgba="0.2 0.2 1 1"/>
  </material>
  <material name="black">
    <color rgba="0 0 0 1"/>
  </material>
  <material name="grey">
    <color rgba="0.2 0.2 0.2 1"/>
  </material>
  <material name="teal">
    <color rgba="0.4 0.5 0.7 1"/>
  </material>
  <material name="red">
    <color rgba="1 0 0 1"/>
  </material>
  <material name="purple">
    <color rgba="1 0 1 1"/>
  </material>
  <link name="chassis_link">
    <visual>
      <origin rpy="0 0 0" xyz="0 0 0"/>
      <geometry>
        <mesh filename="file:///ros2_ws/install/diff_bot/share/diff_bot/mesh/Chassis.stl"/>
      </geometry>
      <material name="teal"/>
    </visual>
    <collision>
      <origin rpy="0 0 0" xyz="0 0 0"/>
      <geometry>
        <mesh filename="file:///ros2_ws/install/diff_bot/share/diff_bot/mesh/Chassis.stl"/>
      </geometry>
    </collision>
    <inertial>
      <origin xyz="0.00276 0 0.024664000000000002"/>
      <mass value="1.674"/>
      <inertia ixx="0.00330292" ixy="0.000000001" ixz="0.000150872" iyy="0.005853202" iyz="0" izz="0.008250538"/>
    </inertial>
  </link>
  <link name="right_wheel_link">
    <visual>
      <origin rpy="0 0 0" xyz="0 0 0"/>
      <geometry>
        <mesh filename="file:///ros2_ws/install/diff_bot/share/diff_bot/mesh/Wheel.stl"/>
      </geometry>
      <material name="grey"/>
    </visual>
    <collision>
      <origin rpy="0 0 0" xyz="0 0 0"/>
      <geometry>
        <mesh filename="file:///ros2_ws/install/diff_bot/share/diff_bot/mesh/Wheel.stl"/>
      </geometry>
    </collision>
    <inertial>
      <origin xyz="0 0 0"/>
      <mass value="0.03"/>
      <inertia ixx="0.000005" ixy="0" ixz="0" iyy="0.000009064" iyz="0" izz="0.000005"/>
    </inertial>
  </link>
  <link name="left_wheel_link">
    <visual>
      <origin rpy="0 0 0" xyz="0 0 0"/>
      <geometry>
        <mesh filename="file:///ros2_ws/install/diff_bot/share/diff_bot/mesh/Wheel.stl"/>
      </geometry>
      <material name="grey"/>
    </visual>
    <collision>
      <origin rpy="0 0 0" xyz="0 0 0"/>
      <geometry>
        <mesh filename="file:///ros2_ws/install/diff_bot/share/diff_bot/mesh/Wheel.stl"/>
      </geometry>
    </collision>
    <inertial>
      <origin xyz="0 0 0"/>
      <mass value="0.03"/>
      <inertia ixx="0.000005" ixy="0" ixz="0" iyy="0.000009064" iyz="0" izz="0.000005"/>
    </inertial>
  </link>
  <link name="lidar_link">
    <visual>
      <geometry>
        <mesh filename="file:///ros2_ws/install/diff_bot/share/diff_bot/mesh/Lidar.stl"/>
      </geometry>
      <material name="purple"/>
    </visual>
    <collision>
      <geometry>
        <mesh filename="file:///ros2_ws/install/diff_bot/share/diff_bot/mesh/Lidar.stl"/>
      </geometry>
    </collision>
    <inertial>
      <origin xyz="0 0 0"/>
      <mass value="0.114"/>
      <inertia ixx="0.000045603" ixy="0" ixz="0" iyy="0.000045603" iyz="0" izz="0.000079502"/>
    </inertial>
  </link>
  <link name="camera_link">
    <visual>
      <geometry>
        <mesh filename="file:///ros2_ws/install/diff_bot/share/diff_bot/mesh/Camera.stl"/>
      </geometry>
      <material name="orange"/>
    </visual>
    <collision>
      <geometry>
        <mesh filename="file:///ros2_ws/install/diff_bot/share/diff_bot/mesh/Camera.stl"/>
      </geometry>
    </collision>
    <inertial>
      <origin xyz="0.004002 0 0"/>
      <mass value="0.05"/>
      <inertia ixx="0.000002401" ixy="0" ixz="0" iyy="0.000001172" iyz="0" izz="0.000001827"/>
    </inertial>
  </link>
  <joint name="right_wheel_joint" type="continuous">
    <parent link="chassis_link"/>
    <child link="right_wheel_link"/>
    <origin rpy="0 0 0" xyz="-0.067 -0.089 0.008"/>
    <axis xyz="0 1 0"/>
  </joint>
  <joint name="left_wheel_joint" type="continuous">
    <parent link="chassis_link"/>
    <child link="left_wheel_link"/>
    <origin rpy="0 0 0" xyz="-0.067 0.089 0.008"/>
    <axis xyz="0 1 0"/>
  </joint>
  <joint name="lidar_joint" type="fixed">
    <parent link="chassis_link"/>
    <child link="lidar_link"/>
    <origin rpy="0 0 0" xyz="0 0 0.0775"/>
  </joint>
  <joint name="camera_joint" type="fixed">
    <parent link="chassis_link"/>
    <child link="camera_link"/>
    <origin rpy="0 0 0" xyz="0.093 0 0.02"/>
  </joint>
  <gazebo>
    <plugin filename="gz-sim-diff-drive-system" name="gz::sim::systems::DiffDrive">
      <!-- Wheel Information -->
      <left_joint>left_wheel_joint</left_joint>
      <right_joint>right_wheel_joint</right_joint>
      <wheel_separation>0.178</wheel_separation>
      <wheel_radius>0.025</wheel_radius>
      <!-- Limits -->
      <max_linear_acceleration>0.33</max_linear_acceleration>
      <topic>cmd_vel</topic>
      <frame_id>odom</frame_id>
      <child_frame_id>base_link</child_frame_id>
      <odom_topic>odom</odom_topic>
      <odom_publisher_frequency>30</odom_publisher_frequency>
      <tf_topic>/tf</tf_topic>
    </plugin>
    <plugin filename="gz-sim-joint-state-publisher-system" name="gz::sim::systems::JointStatePublisher">
      <topic>joint_state</topic>
      <joint_name>left_wheel_joint</joint_name>
      <joint_name>right_wheel_joint</joint_name>
    </plugin>
  </gazebo>
</robot>
