<?xml version="1.0" ?>
<robot name="bot" xmlns:xacro="http://www.ros.org/wiki/xacro">

	<joint name="base_joint" type="fixed">
		<parent link="map" />
		<child link="base_link" />
		<origin xyz="2 1 0" rpy="0 0 0" />
	</joint>

	<joint name="slider_joint" type="prismatic">
		<parent link="base_link" />
		<child link="slider_link" />
		<origin xyz="-${b_x / 2} 0 ${b_z}" rpy="0 0 0" />
		<axis xyz="1 0 0" />
		<limit lower="0" upper="2.5" effort="10" velocity="10" />
	</joint>

	<joint name="arm_joint" type="revolute">
		<parent link="slider_link" />
		<child link="arm_link" />
		<origin rpy="0 0 0" xyz="${s_x / 2} 0 ${s_z}" />
		<axis xyz="0 -1 0" />
		<limit lower="0" upper="${pi / 2}" effort="10" velocity="10" />
	</joint>

	<joint name="camera_joint" type="fixed">
		<parent link="arm_link" />
		<child link="camera_link" />
		<origin rpy="0 0 0" xyz="${a_l} 0 ${a_r + c_h / 2}" />
	</joint>

</robot>
